Workbook
Name BetaFallback: 'Model Inputs'!$B$16
Name TickerCell: DCF!$A$3

Sheet Cover
B2: DCF Valuation Model
B3: Isaiah Moragne, MBA
B4: Equity Valuation via Discounted Cash Flow Analysis
B6: Contact
B7: Website: | C7: https://isaiahmba.com
B8: Email: | C8: isaiahmoragne12@gmail.com
B10: How to Use
B11: 1 | C11: Go to the 'DCF' tab — this is the main output.
B12: 2 | C12: Enter the ticker symbol (e.g. AAPL, MSFT) in the Ticker input cell.
B13: 3 | C13: Refresh data: Data ribbon → Refresh All. This pulls the latest financials, treasury yield, and shares outstanding.
B14: 4 | C14: Review assumptions on 'Model Inputs' and 'WACC' tabs — adjust growth rates, margins, or discount rate as needed.
B15: 5 | C15: Check 'Model Checks' tab to confirm the model ties out before relying on outputs.
B16: 6 | C16: The DCF tab shows the implied share price and upside vs. current market price.
B18: Workbook Tabs
B19: DCF | C19: Main valuation output and summary
B20: Model Inputs | C20: Forecast assumptions (growth, margins, capex, etc.)
B21: WACC | C21: Weighted Average Cost of Capital build
B22: Working Capital | C22: NWC schedule
B23: 3 Statements | C23: Historical Income Statement, Balance Sheet, Cash Flows (from SEC EDGAR)
B24: Historical Actuals | C24: Historical financials used to anchor projections
B25: Data Queries | C25: Live data pulls (treasury, stock info, tax rate, shares, cost of debt)
B26: Model Checks | C26: Integrity checks and tie-outs
B27: Source Audit | C27: Citations and source references
B28: Query Setup | C28: Configuration for data queries
B30: Disclaimer
B31: This model is provided for educational and informational purposes only. It does not constitute investment advice, a recommendation, or a solicitation to buy or sell any security. Outputs depend on third-party data sources and user-supplied assumptions, both of which may contain errors. Always conduct your own due diligence and consult a licensed financial advisor before making investment decisions. The author assumes no liability for any losses or damages arising from use of this model.
B37: © 2026 Isaiah Moragne, MBA. All rights reserved.

Sheet DCF
A1: Dynamic DCF Valuation Model
A2: Ticker | B2: Date
A3: AAPL | B3: =TODAY() -> 46161
A4: Case (1=Bear, 2=Base, 3=Bull) | B4: 2
A5: Selected Case | B5: =IFERROR(CHOOSE($B$4,"Bear","Base","Bull"),"INVALID") -> Base
A7: VALUATION SUMMARY
A8: Sum of PV of FCFs ($) | B8: =SUM(C58:G58) -> 6.4454672e+11
A9: (+) PV of Terminal Value ($) | B9: =B62 -> 1.8745986e+12
A10: Enterprise Value ($) | B10: =B8+B9 -> 2.5191453e+12
A11: (-) Net Debt / (Cash) ($) | B11: =B22 -> 54744000000
A12: Equity Value ($) | B12: =B10+B11 -> 2.5738893e+12
A13: Diluted Shares Outstanding | B13: =B20 -> 15004697000
A14: Implied Share Price | B14: =IFERROR(B12/B13,0) -> 171.53891
A15: Current Share Price | B15: =B19 -> 297.84
A16: Implied Upside / (Downside) | B16: =IFERROR(B14/B15-1,0) -> -0.42405685
A19: Current Stock Price ($) | B19: ='Model Inputs'!B25 -> 297.84
A20: Diluted Shares Outstanding | B20: ='Model Inputs'!B26 -> 15004697000
A21: Market Cap ($) | B21: ='Model Inputs'!B27 -> 4400988977520
A22: Net Debt / (Cash) ($) | B22: ='Model Inputs'!B36 -> 54744000000
A23: Base Fiscal Year | B23: ='Model Inputs'!B39 -> 2025
A24: Base Revenue Source | B24: ='Model Inputs'!D28 -> OK
A25: Current Shares Outstanding | B25: ='Model Inputs'!B40 -> 14776353000
A27: SELECTED CASE ASSUMPTIONS
A28: Assumption | B28: FY1 | C28: FY2 | D28: FY3 | E28: FY4 | F28: FY5
A29: Revenue Growth (%) | B29: =CHOOSE($B$4,'Model Inputs'!B45,'Model Inputs'!B55,'Model Inputs'!B65) -> 0.08 | C29: =CHOOSE($B$4,'Model Inputs'!C45,'Model Inputs'!C55,'Model Inputs'!C65) -> 0.1 | D29: =CHOOSE($B$4,'Model Inputs'!D45,'Model Inputs'!D55,'Model Inputs'!D65) -> 0.08 | E29: =CHOOSE($B$4,'Model Inputs'!E45,'Model Inputs'!E55,'Model Inputs'!E65) -> 0.06 | F29: =CHOOSE($B$4,'Model Inputs'!F45,'Model Inputs'!F55,'Model Inputs'!F65) -> 0.04
A30: EBIT Margin (%) | B30: =CHOOSE($B$4,'Model Inputs'!B46,'Model Inputs'!B56,'Model Inputs'!B66) -> 0.339708 | C30: =CHOOSE($B$4,'Model Inputs'!C46,'Model Inputs'!C56,'Model Inputs'!C66) -> 0.359708 | D30: =CHOOSE($B$4,'Model Inputs'!D46,'Model Inputs'!D56,'Model Inputs'!D66) -> 0.379708 | E30: =CHOOSE($B$4,'Model Inputs'!E46,'Model Inputs'!E56,'Model Inputs'!E66) -> 0.389708 | F30: =CHOOSE($B$4,'Model Inputs'!F46,'Model Inputs'!F56,'Model Inputs'!F66) -> 0.399708
A31: Tax Rate (%) | B31: =CHOOSE($B$4,'Model Inputs'!B47,'Model Inputs'!B57,'Model Inputs'!B67) -> 0.15610002 | C31: =CHOOSE($B$4,'Model Inputs'!C47,'Model Inputs'!C57,'Model Inputs'!C67) -> 0.15610002 | D31: =CHOOSE($B$4,'Model Inputs'!D47,'Model Inputs'!D57,'Model Inputs'!D67) -> 0.15610002 | E31: =CHOOSE($B$4,'Model Inputs'!E47,'Model Inputs'!E57,'Model Inputs'!E67) -> 0.15610002 | F31: =CHOOSE($B$4,'Model Inputs'!F47,'Model Inputs'!F57,'Model Inputs'!F67) -> 0.15610002
A32: D&A (% of Revenue) | B32: =CHOOSE($B$4,'Model Inputs'!B48,'Model Inputs'!B58,'Model Inputs'!B68) -> 0.028109313 | C32: =CHOOSE($B$4,'Model Inputs'!C48,'Model Inputs'!C58,'Model Inputs'!C68) -> 0.028109313 | D32: =CHOOSE($B$4,'Model Inputs'!D48,'Model Inputs'!D58,'Model Inputs'!D68) -> 0.028109313 | E32: =CHOOSE($B$4,'Model Inputs'!E48,'Model Inputs'!E58,'Model Inputs'!E68) -> 0.028109313 | F32: =CHOOSE($B$4,'Model Inputs'!F48,'Model Inputs'!F58,'Model Inputs'!F68) -> 0.028109313
A33: CapEx (% of Revenue) | B33: =CHOOSE($B$4,'Model Inputs'!B49,'Model Inputs'!B59,'Model Inputs'!B69) -> 0.030553079 | C33: =CHOOSE($B$4,'Model Inputs'!C49,'Model Inputs'!C59,'Model Inputs'!C69) -> 0.030553079 | D33: =CHOOSE($B$4,'Model Inputs'!D49,'Model Inputs'!D59,'Model Inputs'!D69) -> 0.030553079 | E33: =CHOOSE($B$4,'Model Inputs'!E49,'Model Inputs'!E59,'Model Inputs'!E69) -> 0.030553079 | F33: =CHOOSE($B$4,'Model Inputs'!F49,'Model Inputs'!F59,'Model Inputs'!F69) -> 0.030553079
A34: Change in NWC (% of Change in Revenue) | B34: =CHOOSE($B$4,'Model Inputs'!B50,'Model Inputs'!B60,'Model Inputs'!B70) -> 0.03 | C34: =CHOOSE($B$4,'Model Inputs'!C50,'Model Inputs'!C60,'Model Inputs'!C70) -> 0.03 | D34: =CHOOSE($B$4,'Model Inputs'!D50,'Model Inputs'!D60,'Model Inputs'!D70) -> 0.03 | E34: =CHOOSE($B$4,'Model Inputs'!E50,'Model Inputs'!E60,'Model Inputs'!E70) -> 0.03 | F34: =CHOOSE($B$4,'Model Inputs'!F50,'Model Inputs'!F60,'Model Inputs'!F70) -> 0.03
A35: Terminal Growth Rate | B35: =CHOOSE($B$4,'Model Inputs'!B51,'Model Inputs'!B61,'Model Inputs'!B71) -> 0.03
A36: WACC | B36: =CHOOSE($B$4,'Model Inputs'!B52,'Model Inputs'!B62,'Model Inputs'!B72) -> 0.097716646
A39: CASH FLOW PROJECTIONS ($)
A40: ($) | B40: LTM / Base FY | C40: FY1E | D40: FY2E | E40: FY3E | F40: FY4E | G40: FY5E
A41: Revenue | B41: ='Model Inputs'!B28 -> 416161000000 | C41: =B41*(1+B29) -> 449453880000 | D41: =C41*(1+C29) -> 4.9439927e+11 | E41: =D41*(1+D29) -> 5.3395121e+11 | F41: =E41*(1+E29) -> 5.6598828e+11 | G41: =F41*(1+F29) -> 5.8862781e+11
A42: % growth | C42: =C41/B41-1 -> 0.08 | D42: =D41/C41-1 -> 0.1 | E42: =E41/D41-1 -> 0.08 | F42: =F41/E41-1 -> 0.06 | G42: =G41/F41-1 -> 0.04
A43: EBIT | B43: ='Model Inputs'!B29 -> 133050000000 | C43: =C41*B30 -> 1.5268308e+11 | D43: =D41*C30 -> 1.7783937e+11 | E43: =E41*D30 -> 2.0274554e+11 | F43: =F41*E30 -> 2.2057016e+11 | G43: =G41*F30 -> 2.3527924e+11
A44: % margin | B44: =B43/B41 -> 0.319708 | C44: =C43/C41 -> 0.339708 | D44: =D43/D41 -> 0.359708 | E44: =E43/E41 -> 0.379708 | F44: =F43/F41 -> 0.389708 | G44: =G43/G41 -> 0.399708
A45: (-) Taxes | C45: =-C43*B31 -> -2.3833832e+10 | D45: =-D43*C31 -> -2.776073e+10 | E45: =-E43*D31 -> -3.1648584e+10 | F45: =-F43*E31 -> -3.4431007e+10 | G45: =-G43*F31 -> -3.6727096e+10
A46: NOPAT | C46: =C43+C45 -> 1.2884925e+11 | D46: =D43+D45 -> 1.5007864e+11 | E46: =E43+E45 -> 1.7109696e+11 | F46: =F43+F45 -> 1.8613915e+11 | G46: =G43+G45 -> 1.9855215e+11
...

Sheet Model Inputs
A1: Dynamic DCF Model Inputs & Controls
A3: Ticker | B3: =DCF!A3 -> AAPL
A4: Valuation Date | B4: =DCF!B3 -> 46161
A6: Manual / Override Inputs
A7: Current Share Price ($) | B7: 0 | C7: =IF(B7=0,FALSE,TRUE) -> FALSE | D7: Used when StockInformation Previous Close is blank or override is TRUE.
A8: Diluted Shares | B8: 0 | C8: =IF(B8=0,FALSE,TRUE) -> FALSE | D8: Fallback to latest diluted weighted average shares or EDGAR shares outstanding.
A9: Base Revenue ($) | B9: 0 | C9: =IF(B9=0,FALSE,TRUE) -> FALSE | D9: Fallback if revenue query is blank; current AMD FY2025 revenue inferred from SEC filing.
A10: Base EBIT / Operating Income ($) | B10: 0 | C10: =IF(B10=0,FALSE,TRUE) -> FALSE | D10: Fallback if Operating Income query is blank.
A11: D&A (% Revenue) | B11: 0 | C11: =IF(B11=0,FALSE,TRUE) -> FALSE | D11: Fallback because current query often returns stale D&A. Edit after adding a clean cash flow query.
A12: CapEx ($) | B12: 0 | C12: =IF(B12=0,FALSE,TRUE) -> FALSE | D12: Fallback if CapEx query is blank or stale.
A13: Cash & Equivalents ($) | B13: 0 | C13: =IF(B13=0,FALSE,TRUE) -> FALSE | D13: Fallback if balance sheet cash query is blank.
A14: Gross Debt ($) | B14: 0 | C14: =IF(B14=0,FALSE,TRUE) -> FALSE | D14: Override is TRUE because the current query appears to miss current debt.
A15: Normalized Cash Tax Rate | B15: 0 | C15: =IF(B15=0,FALSE,TRUE) -> FALSE | D15: Fallback if actual tax is negative/unusual.
A16: Beta | B16: 0 | C16: =IF(B16=0,FALSE,TRUE) -> FALSE | D16: Manual beta fallback if market-data beta is unavailable.
A17: Risk-Free Rate | B17: 0 | C17: =IF(B17=0,FALSE,TRUE) -> FALSE | D17: Fallback if 10Y Treasury query is blank.
A18: Equity Risk Premium | B18: 0.05 | C18: =IF(B18=0,FALSE,TRUE) -> TRUE | D18: Manual market assumption.
A19: Pre-Tax Cost of Debt | B19: 0 | C19: =IF(B19=0,FALSE,TRUE) -> FALSE | D19: Fallback if debt cost query is negative or implausibly high.
A20: NWC (% of Change in Revenue) | B20: =0.03 -> 0.03 | C20: Manual operating working capital assumption.
A21: Terminal Growth | B21: =0.03 -> 0.03 | C21: Manual long-term nominal growth assumption.
A22: Terminal Value Discount Timing | B22: Year-End | C22: Manual | D22: Use Mid-Year or Year-End; terminal value and sensitivities follow this setting.
A23: NWC Forecast Method | B23: Manual % of Revenue Change | C23: Manual | D23: Working Capital sheet provides actual operating NWC cross-check.
A24: Controlled Model Outputs
A25: Current Share Price ($) | B25: =_xlfn.LET(_xlpm.raw,IFERROR('Data Queries'!E2,0),_xlpm.q,IFERROR(_xlfn.NUMBERVALUE(_xlpm.raw),0),IF(AND($C$7,B7<>0),B7,IF(_xlpm.q>0,_xlpm.q,B7))) -> 297.84 | C25: StockInformation Previous Close, else manual B7 | D25: =IF(B25>0,"OK","MISSING") -> OK
A26: Diluted Shares | B26: =_xlfn.LET(_xlpm.dil,IFERROR(_xlfn.XLOOKUP("*Shares*Diluted*",EDGAR_IncomeStatement[Line Item],EDGAR_IncomeStatement[Value],0,2),0),_xlpm.so,IFERROR(INDEX(EDGAR_SharesOutstanding[Shares Outstanding],1),0),IF(AND($C$8,B8<>0),B8,IF(_xlpm.dil>0,_xlpm.dil,IF(_xlpm.so>0,_xlpm.so,B8)))) -> 15004697000 | C26: Diluted weighted average shares, then EDGAR shares outstanding, then manual B8 | D26: =IF(B26>0,"OK","MISSING") -> OK
A27: Market Cap ($) | B27: =B25*IF(B40>0,B40,B26) -> 4400988977520 | C27: Price x current shares outstanding; falls back to diluted shares if needed | D27: =IF(B27>0,"OK","MISSING") -> OK
A28: Base Revenue ($) | B28: =_xlfn.LET(_xlpm.rev,IFERROR(_xlfn.XLOOKUP("Total Revenue",EDGAR_IncomeStatement[Line Item],EDGAR_IncomeStatement[Value],0,0),0),_xlpm.gross,IFERROR(_xlfn.XLOOKUP("Gross Profit",EDGAR_IncomeStatement[Line Item],EDGAR_IncomeStatement[Value],0,0),0),_xlpm.cogs,IFERROR(_xlfn.XLOOKUP("Cost of Goods & Services Sold",EDGAR_IncomeStatement[Line Item],EDGAR_IncomeStatement[Value],0,0),0),_xlpm.costrev,IFERROR(_xlfn.XLOOKUP("Cost of Revenue",EDGAR_IncomeStatement[Line Item],EDGAR_IncomeStatement[Value],0,0),0),_xlpm.alt,_xlpm.gross+MAX(_xlpm.cogs,_xlpm.costrev),IF(AND($C$9,B9<>0),B9,IF(_xlpm.rev>0,_xlpm.rev,IF(_xlpm.alt>0,_xlpm.alt,B9)))) -> 416161000000 | C28: Total Revenue, or Gross Profit + Cost of Revenue, else manual B9 | D28: =_xlfn.LET(_xlpm.rev,IFERROR(_xlfn.XLOOKUP("Total Revenue",EDGAR_IncomeStatement[Line Item],EDGAR_IncomeStatement[Value],0,0),0),_xlpm.gross,IFERROR(_xlfn.XLOOKUP("Gross Profit",EDGAR_IncomeStatement[Line Item],EDGAR_IncomeStatement[Value],0,0),0),_xlpm.cogs,IFERROR(_xlfn.XLOOKUP("Cost of Goods & Services Sold",EDGAR_IncomeStatement[Line Item],EDGAR_IncomeStatement[Value],0,0),0),_xlpm.costrev,IFERROR(_xlfn.XLOOKUP("Cost of Revenue",EDGAR_IncomeStatement[Line Item],EDGAR_IncomeStatement[Value],0,0),0),_xlpm.alt,_xlpm.gross+MAX(_xlpm.cogs,_xlpm.costrev),IF(AND($C$9,B9<>""),"OVERRIDE",IF(_xlpm.rev>0,"OK",IF(_xlpm.alt>0,"INFERRED","FALLBACK")))) -> OK
A29: Base EBIT / Operating Income ($) | B29: =_xlfn.LET(_xlpm.q,IFERROR(_xlfn.XLOOKUP("Operating Income (Loss)",EDGAR_IncomeStatement[Line Item],EDGAR_IncomeStatement[Value],0,0),0),IF(AND($C$10,B10<>0),B10,IF(_xlpm.q<>0,_xlpm.q,B10))) -> 133050000000 | C29: Operating Income (Loss), else manual B10 | D29: =IF(B29<>0,"OK","MISSING") -> OK
A30: Base EBIT Margin | B30: =IFERROR(B29/B28,0) -> 0.319708 | C30: Operating income / revenue | D30: =IF(B30>0,"OK","CHECK") -> OK
A31: Normalized Cash Tax Rate | B31: =_xlfn.LET(_xlpm.pbt,IFERROR(_xlfn.XLOOKUP("Income Before Tax",EDGAR_IncomeStatement[Line Item],EDGAR_IncomeStatement[Value],0,0),0),_xlpm.tax,IFERROR(_xlfn.XLOOKUP("Income Tax Expense (Benefit)",EDGAR_IncomeStatement[Line Item],EDGAR_IncomeStatement[Value],0,0),0),IF(AND($C$15,B15<>0),B15,IF(AND(_xlpm.pbt>0,_xlpm.tax>0,_xlpm.tax/_xlpm.pbt<0.4),_xlpm.tax/_xlpm.pbt,B15))) -> 0.15610002 | C31: Actual tax/PBT if normal, else manual B15 | D31: =IF(AND(B31>0,B31<0.4),"OK","CHECK") -> OK
A32: D&A (% Revenue) | B32: =_xlfn.LET(_xlpm.val,IFERROR(_xlfn.XLOOKUP("*Depreciation*",EDGAR_StatementOfCashFlows[Line Item],EDGAR_StatementOfCashFlows[Value (USD)],0,2),0),_xlpm.fy,IFERROR(_xlfn.XLOOKUP("*Depreciation*",EDGAR_StatementOfCashFlows[Line Item],EDGAR_StatementOfCashFlows[FY],0,2),0),_xlpm.manual,B11,IF(AND($C$11,_xlpm.manual<>0),_xlpm.manual,IF(AND(_xlpm.val>0,_xlpm.fy=$B$39,$B$28>0),_xlpm.val/$B$28,_xlpm.manual))) -> 0.028109313 | C32: Current-year D&A if fresh; otherwise manual B11 | D32: =IF(AND(B32>0,B32<0.3),"OK","CHECK") -> OK
A33: CapEx (% Revenue) | B33: =_xlfn.LET(_xlpm.val,IFERROR(_xlfn.XLOOKUP("Capital Expenditures",EDGAR_StatementOfCashFlows[Line Item],EDGAR_StatementOfCashFlows[Value (USD)],0,0),0),_xlpm.fy,IFERROR(_xlfn.XLOOKUP("Capital Expenditures",EDGAR_StatementOfCashFlows[Line Item],EDGAR_StatementOfCashFlows[FY],0,0),0),_xlpm.manual,IFERROR(B12/$B$28,0),IF(AND($C$12,B12<>0),_xlpm.manual,IF(AND(_xlpm.val<>0,_xlpm.fy=$B$39,$B$28>0),ABS(_xlpm.val)/$B$28,_xlpm.manual))) -> 0.030553079 | C33: Current-year CapEx / revenue, else manual B12 / revenue | D33: =IF(AND(B33>0,B33<0.3),"OK","CHECK") -> OK
A34: Cash & Equivalents ($) | B34: =_xlfn.LET(_xlpm.q,IFERROR(_xlfn.XLOOKUP("Cash & Equivalents",EDGAR_BalanceSheet[Line Item],EDGAR_BalanceSheet[Value (USD)],0,0),0),IF(AND($C$13,B13<>0),B13,IF(_xlpm.q>0,_xlpm.q,B13))) -> 35934000000 | C34: Balance sheet cash, else manual B13 | D34: =IF(B34>=0,"OK","CHECK") -> OK
A35: Gross Debt ($) | B35: =_xlfn.LET(_xlpm.st,IFERROR(_xlfn.XLOOKUP("Short-Term Debt",EDGAR_BalanceSheet[Line Item],EDGAR_BalanceSheet[Value (USD)],0,0),0),_xlpm.lt,IFERROR(_xlfn.XLOOKUP("Long-Term Debt",EDGAR_BalanceSheet[Line Item],EDGAR_BalanceSheet[Value (USD)],0,0),0),_xlpm.q,_xlpm.st+_xlpm.lt,IF(AND($C$14,B14<>0),B14,IF(_xlpm.q>=0,_xlpm.q,B14))) -> 90678000000 | C35: Short-term + long-term debt, or manual B14 | D35: =IF(B35>=0,"OK","CHECK") -> OK
A36: Net Debt / (Cash) ($) | B36: =B35-B34 -> 54744000000 | C36: Gross debt - cash | D36: =IF(ISNUMBER(B36),"OK","CHECK") -> OK
A37: NWC (% of Change in Revenue) | B37: =B20 -> 0.03 | C37: Manual operating assumption | D37: =IF(AND(B37>=-0.2,B37<=0.3),"OK","CHECK") -> OK
A38: Terminal Growth | B38: =B21 -> 0.03 | C38: Manual long-term assumption | D38: =IF(B38<WACC!$B$22,"OK","INVALID: g >= WACC") -> OK
A39: Base Fiscal Year | B39: =MAX(IFERROR(MAX(EDGAR_IncomeStatement[FY]),0),IFERROR(MAX(EDGAR_BalanceSheet[FY]),0),IFERROR(MAX(EDGAR_StatementOfCashFlows[FY]),0)) -> 2025 | C39: Max FY across query tables | D39: =IF(B39>0,"OK","MISSING") -> OK
A40: Current Shares Outstanding | B40: =_xlfn.LET(_xlpm.so,IFERROR(INDEX(EDGAR_SharesOutstanding[Shares Outstanding],1),0),IF(_xlpm.so>0,_xlpm.so,B26)) -> 14776353000 | C40: EDGAR shares outstanding, else diluted shares fallback | D40: =IF(B40>0,"OK","MISSING") -> OK
A42: Scenario Assumptions
A44: BEAR CASE
...

Sheet WACC
A1: WACC Calculation
A3: COST OF EQUITY (CAP
A4: Risk-Free Rate | B4: =_xlfn.LET(_xlpm.raw,IFERROR('Data Queries'!B2,""),_xlpm.q,IFERROR(IF(ISNUMBER(_xlpm.raw),_xlpm.raw,_xlfn.NUMBERVALUE(SUBSTITUTE(_xlpm.raw,"%",""))/100),0),IF(AND('Model Inputs'!$C$17,'Model Inputs'!$B$17<>0),'Model Inputs'!$B$17,IF(_xlpm.q>0,_xlpm.q,'Model Inputs'!$B$17))) -> 0.04623 | C4: 10Y Treasury query, else Model Inputs B17
A5: Equity Risk Premium | B5: ='Model Inputs'!B18 -> 0.05 | C5: Manual ERP
A6: Beta | B6: =_xlfn.LET(_xlpm.raw,IFERROR('Data Queries'!E11,0),_xlpm.q,IFERROR(_xlfn.NUMBERVALUE(_xlpm.raw),0),_xlpm.manual,'Model Inputs'!$B$16,IF(AND('Model Inputs'!$C$16,_xlpm.manual<>0),_xlpm.manual,IF(_xlpm.q>0,_xlpm.q,_xlpm.manual))) -> 1.07 | C6: StockInformation beta, else Model Inputs B16
A7: Cost of Equity | B7: =B4+B6*B5 -> 0.09973 | C7: Rf + beta x ERP
A9: COST OF DEBT
A10: Pre-Tax Cost of Debt | B10: =_xlfn.LET(_xlpm.q,ABS(IFERROR(INDEX(Cost_of_Debt[Pre-Tax Cost of Debt],1),0)),_xlpm.fy,IFERROR(INDEX(Cost_of_Debt[FY],1),0),IF(AND('Model Inputs'!$C$19,'Model Inputs'!$B$19<>0),'Model Inputs'!$B$19,IF(AND(_xlpm.fy='Model Inputs'!$B$39,_xlpm.q>0,_xlpm.q<0.3),_xlpm.q,'Model Inputs'!$B$19))) -> 0 | C10: Positive query result when plausible; else manual B19
A11: Tax Rate | B11: ='Model Inputs'!B31 -> 0.15610002 | C11: Normalized tax rate
A12: After-Tax Cost of Debt | B12: =B10*(1-B11) -> 0 | C12: Pre-tax cost x (1-tax rate)
A14: CAPITAL STRUCTURE ($)
A15: Market Cap | B15: ='Model Inputs'!B27 -> 4400988977520 | C15: =_xlfn.FORMULATEXT(B15) -> ='Model Inputs'!B27
A16: Gross Debt | B16: ='Model Inputs'!B35 -> 90678000000 | C16: =_xlfn.FORMULATEXT(B16) -> ='Model Inputs'!B35
A17: Cash & Equivalents | B17: ='Model Inputs'!B34 -> 35934000000 | C17: =_xlfn.FORMULATEXT(B17) -> ='Model Inputs'!B34
A18: Net Debt / (Cash) | B18: ='Model Inputs'!B36 -> 54744000000 | C18: =_xlfn.FORMULATEXT(B18) -> ='Model Inputs'!B36
A19: Capital Base for Weights | B19: =B15+B16 -> 4491666977520 | C19: =_xlfn.FORMULATEXT(B19) -> =B15+B16
A20: Equity Weight | B20: =IFERROR(B15/B19,0) -> 0.97981195 | C20: =_xlfn.FORMULATEXT(B20) -> =IFERROR(B15/B19,0)
A21: Debt Weight | B21: =IFERROR(B16/B19,0) -> 0.020188051 | C21: =_xlfn.FORMULATEXT(B21) -> =IFERROR(B16/B19,0)
A22: WACC | B22: =B7*B20+B12*B21 -> 0.097716646 | C22: =_xlfn.FORMULATEXT(B22) -> =B7*B20+B12*B21

Sheet Working Capital
A1: Working Capital Cross-Check
A3: Item | B3: Current Value ($)
A4: Accounts Receivable | B4: =_xlfn.XLOOKUP("Accounts Receivable, Net",EDGAR_BalanceSheet[Line Item],EDGAR_BalanceSheet[Value (USD)],0,0) -> 39777000000
A5: Inventory | B5: =_xlfn.XLOOKUP("Inventory",EDGAR_BalanceSheet[Line Item],EDGAR_BalanceSheet[Value (USD)],0,0) -> 5718000000
A6: Other Current Assets | B6: =_xlfn.XLOOKUP("Other Current Assets",EDGAR_BalanceSheet[Line Item],EDGAR_BalanceSheet[Value (USD)],0,0) -> 47765000000
A7: Accounts Payable | B7: =_xlfn.XLOOKUP("Accounts Payable",EDGAR_BalanceSheet[Line Item],EDGAR_BalanceSheet[Value (USD)],0,0) -> 69860000000
A8: Accrued Liabilities | B8: =_xlfn.XLOOKUP("Accrued Liabilities",EDGAR_BalanceSheet[Line Item],EDGAR_BalanceSheet[Value (USD)],0,0) -> 13016000000
A9: Other Current Liabilities | B9: =_xlfn.XLOOKUP("Other Current Liabilities",EDGAR_BalanceSheet[Line Item],EDGAR_BalanceSheet[Value (USD)],0,0) -> 70405000000
A10: Operating NWC | B10: =B4+B5+B6-B7-B8-B9 -> -60021000000
A11: Revenue | B11: =_xlfn.XLOOKUP("Total Revenue",EDGAR_IncomeStatement[Line Item],EDGAR_IncomeStatement[Value],0,0) -> 416161000000
A12: Operating NWC % Revenue | B12: =IFERROR(B10/B11,0) -> -0.14422543
A13: DCF NWC Assumption | B13: =DCF!B34 -> 0.03
A15: Note | B15: This is a cross-check only. The DCF still uses the explicit NWC % of revenue-change assumption unless you choose to replace it.

Sheet 3 Statements
B1: Balance Sheet | J1: Income Statement | R1: Statement of Cash Flows
B2: Company | C2: Line Item | D2: Value (USD) | E2: Period End | F2: FY | G2: Filed | J2: FY | K2: Company | L2: Line Item | M2: Value | N2: Period End | O2: Filed | R2: FY | S2: Company | T2: Line Item | U2: Value (USD) | V2: Period End | W2: Filed
B3: Apple Inc. | C3: Cash & Equivalents | D3: 35934000000 | E3: 45927 | F3: 2025 | G3: 45961 | J3: 2025 | K3: Apple Inc. | L3: Total Revenue | M3: 416161000000 | N3: 45927 | O3: 45961 | R3: 2025 | S3: Apple Inc. | T3: Net Income | U3: 112010000000 | V3: 45927 | W3: 45961
B4: Apple Inc. | C4: Short-Term Investments | D4: 18763000000 | E4: 45927 | F4: 2025 | G4: 45961 | J4: 2025 | K4: Apple Inc. | L4: Cost of Revenue | M4: 220960000000 | N4: 45927 | O4: 45961 | R4: 2025 | S4: Apple Inc. | T4: Depreciation, Depletion & Amortization | U4: 11698000000 | V4: 45927 | W4: 45961
B5: Apple Inc. | C5: Accounts Receivable, Net | D5: 39777000000 | E5: 45927 | F5: 2025 | G5: 45961 | J5: 2025 | K5: Apple Inc. | L5: Cost of Goods & Services Sold | M5: 220960000000 | N5: 45927 | O5: 45961 | R5: 2025 | S5: Apple Inc. | T5: Stock-Based Compensation | U5: 12863000000 | V5: 45927 | W5: 45961
B6: Apple Inc. | C6: Inventory | D6: 5718000000 | E6: 45927 | F6: 2025 | G6: 45961 | J6: 2025 | K6: Apple Inc. | L6: Gross Profit | M6: 195201000000 | N6: 45927 | O6: 45961 | S6: Apple Inc. | T6: Deferred Income Tax Expense
B7: Apple Inc. | C7: Other Current Assets | D7: 47765000000 | E7: 45927 | F7: 2025 | G7: 45961 | J7: 2025 | K7: Apple Inc. | L7: Research & Development Expense | M7: 34550000000 | N7: 45927 | O7: 45961 | R7: 2025 | S7: Apple Inc. | T7: Change in Accounts Receivable | U7: 6682000000 | V7: 45927 | W7: 45961
B8: Apple Inc. | C8: Total Current Assets | D8: 147957000000 | E8: 45927 | F8: 2025 | G8: 45961 | J8: 2025 | K8: Apple Inc. | L8: Selling, General & Admin Expense | M8: 27601000000 | N8: 45927 | O8: 45961 | R8: 2025 | S8: Apple Inc. | T8: Change in Inventory | U8: -1400000000 | V8: 45927 | W8: 45961
B9: Apple Inc. | C9: PP&E, Net | D9: 49834000000 | E9: 45927 | F9: 2025 | G9: 45961 | J9: 2025 | K9: Apple Inc. | L9: Depreciation, Depletion & Amortization | M9: 11698000000 | N9: 45927 | O9: 45961 | R9: 2025 | S9: Apple Inc. | T9: Change in Accounts Payable | U9: 902000000 | V9: 45927 | W9: 45961
B10: Apple Inc. | C10: Goodwill | J10: 2025 | K10: Apple Inc. | L10: Total Operating Expenses | M10: 62151000000 | N10: 45927 | O10: 45961 | S10: Apple Inc. | T10: Change in Other Working Capital
B11: Apple Inc. | C11: Intangible Assets, Net | J11: 2025 | K11: Apple Inc. | L11: Operating Income (Loss) | M11: 133050000000 | N11: 45927 | O11: 45961 | R11: 2025 | S11: Apple Inc. | T11: Cash from Operating Activities | U11: 111482000000 | V11: 45927 | W11: 45961
B12: Apple Inc. | C12: Other Non-Current Assets | D12: 83727000000 | E12: 45927 | F12: 2025 | G12: 45961 | K12: Apple Inc. | L12: Interest Expense | R12: 2025 | S12: Apple Inc. | T12: Capital Expenditures | U12: 12715000000 | V12: 45927 | W12: 45961
B13: Apple Inc. | C13: Total Assets | D13: 359241000000 | E13: 45927 | F13: 2025 | G13: 45961 | J13: 2025 | K13: Apple Inc. | L13: Other Non-Operating Income (Expense) | M13: -321000000 | N13: 45927 | O13: 45961 | S13: Apple Inc. | T13: Acquisitions, Net of Cash
B14: Apple Inc. | C14: Accounts Payable | D14: 69860000000 | E14: 45927 | F14: 2025 | G14: 45961 | J14: 2025 | K14: Apple Inc. | L14: Income Before Tax | M14: 132729000000 | N14: 45927 | O14: 45961 | S14: Apple Inc. | T14: Proceeds from Sale of PP&E
B15: Apple Inc. | C15: Accrued Liabilities | D15: 13016000000 | E15: 45927 | F15: 2025 | G15: 45961 | J15: 2025 | K15: Apple Inc. | L15: Income Tax Expense (Benefit) | M15: 20719000000 | N15: 45927 | O15: 45961 | S15: Apple Inc. | T15: Purchase of Investments
B16: Apple Inc. | C16: Short-Term Debt | D16: 12350000000 | E16: 45927 | F16: 2025 | G16: 45961 | J16: 2025 | K16: Apple Inc. | L16: Net Income | M16: 112010000000 | N16: 45927 | O16: 45961 | S16: Apple Inc. | T16: Proceeds from Sale of Investments
B17: Apple Inc. | C17: Other Current Liabilities | D17: 70405000000 | E17: 45927 | F17: 2025 | G17: 45961 | J17: 2025 | K17: Apple Inc. | L17: EPS - Basic | M17: 7.49 | N17: 45927 | O17: 45961 | R17: 2025 | S17: Apple Inc. | T17: Cash from Investing Activities | U17: 15195000000 | V17: 45927 | W17: 45961
B18: Apple Inc. | C18: Total Current Liabilities | D18: 165631000000 | E18: 45927 | F18: 2025 | G18: 45961 | J18: 2025 | K18: Apple Inc. | L18: EPS - Diluted | M18: 7.46 | N18: 45927 | O18: 45961 | R18: 2025 | S18: Apple Inc. | T18: Debt Issuance | U18: 4481000000 | V18: 45927 | W18: 45961
B19: Apple Inc. | C19: Long-Term Debt | D19: 78328000000 | E19: 45927 | F19: 2025 | G19: 45961 | J19: 2025 | K19: Apple Inc. | L19: Weighted Avg Shares - Basic | M19: 14948500000 | N19: 45927 | O19: 45961 | R19: 2025 | S19: Apple Inc. | T19: Debt Repayment | U19: 10932000000 | V19: 45927 | W19: 45961
B20: Apple Inc. | C20: Deferred Tax Liabilities | D20: 7471000000 | E20: 45927 | F20: 2025 | G20: 45961 | J20: 2025 | K20: Apple Inc. | L20: Weighted Avg Shares - Diluted | M20: 15004697000 | N20: 45927 | O20: 45961 | R20: 2025 | S20: Apple Inc. | T20: Common Stock Repurchase | U20: 90711000000 | V20: 45927 | W20: 45961
B21: Apple Inc. | C21: Other Non-Current Liabilities | D21: 41549000000 | E21: 45927 | F21: 2025 | G21: 45961 | R21: 2025 | S21: Apple Inc. | T21: Dividends Paid | U21: 15421000000 | V21: 45927 | W21: 45961
B22: Apple Inc. | C22: Total Liabilities | D22: 285508000000 | E22: 45927 | F22: 2025 | G22: 45961 | R22: 2025 | S22: Apple Inc. | T22: Cash from Financing Activities | U22: -120686000000 | V22: 45927 | W22: 45961
B23: Apple Inc. | C23: Common Stock | R23: 2025 | S23: Apple Inc. | T23: Net Change in Cash | U23: 5991000000 | V23: 45927 | W23: 45961
B24: Apple Inc. | C24: Additional Paid-In Capital | D24: 93568000000 | E24: 45927 | F24: 2025 | G24: 45961 | R24: 2025 | S24: Apple Inc. | T24: Cash & Equivalents - Beginning | U24: 29943000000 | V24: 45927 | W24: 45961
B25: Apple Inc. | C25: Retained Earnings | D25: -14264000000 | E25: 45927 | F25: 2025 | G25: 45961 | S25: Apple Inc. | T25: Interest Paid
B26: Apple Inc. | C26: Treasury Stock | R26: 2025 | S26: Apple Inc. | T26: Income Taxes Paid | U26: 43369000000 | V26: 45927 | W26: 45961
B27: Apple Inc. | C27: Accumulated OCI | D27: -5571000000 | E27: 45927 | F27: 2025 | G27: 45961
B28: Apple Inc. | C28: Total Stockholders' Equity | D28: 73733000000 | E28: 45927 | F28: 2025 | G28: 45961
B29: Apple Inc. | C29: Total Liabilities & Equity | D29: 359241000000 | E29: 45927 | F29: 2025 | G29: 45961

Sheet Historical Actuals
A1: Historical / Base Actuals
A3: Metric | B3: FY | C3: Value | D3: Source
A4: Revenue | B4: ='Model Inputs'!B39 -> 2025 | C4: =_xlfn.XLOOKUP("Total Revenue",EDGAR_IncomeStatement[Line Item],EDGAR_IncomeStatement[Value],0,0) -> 416161000000 | D4: EDGAR_IncomeStatement
A5: EBIT | B5: ='Model Inputs'!B39 -> 2025 | C5: =_xlfn.XLOOKUP("Operating Income (Loss)",EDGAR_IncomeStatement[Line Item],EDGAR_IncomeStatement[Value],0,0) -> 133050000000 | D5: EDGAR_IncomeStatement
A6: EBIT Margin | B6: ='Model Inputs'!B39 -> 2025 | C6: =IFERROR(C5/C4,0) -> 0.319708 | D6: Derived
A7: D&A | B7: ='Model Inputs'!B39 -> 2025 | C7: =_xlfn.XLOOKUP("Depreciation, Depletion & Amortization",EDGAR_StatementOfCashFlows[Line Item],EDGAR_StatementOfCashFlows[Value (USD)],0,0) -> 11698000000 | D7: EDGAR_StatementOfCashFlows
A8: CapEx | B8: ='Model Inputs'!B39 -> 2025 | C8: =_xlfn.XLOOKUP("Capital Expenditures",EDGAR_StatementOfCashFlows[Line Item],EDGAR_StatementOfCashFlows[Value (USD)],0,0) -> 12715000000 | D8: EDGAR_StatementOfCashFlows
A9: Cash | B9: ='Model Inputs'!B39 -> 2025 | C9: =_xlfn.XLOOKUP("Cash & Equivalents",EDGAR_BalanceSheet[Line Item],EDGAR_BalanceSheet[Value (USD)],0,0) -> 35934000000 | D9: EDGAR_BalanceSheet
A10: Gross Debt | B10: ='Model Inputs'!B39 -> 2025 | C10: ='Model Inputs'!B35 -> 90678000000 | D10: Derived from BS debt lines
A11: Diluted Shares | B11: ='Model Inputs'!B39 -> 2025 | C11: ='Model Inputs'!B26 -> 15004697000 | D11: EDGAR_IncomeStatement

Sheet Model Checks
A1: Model Checks
A2: =IF(COUNTIF(D4:D48,"FAIL")>0,"FAIL",IF(COUNTIF(D4:D48,"WARN")>0,"WARN","PASS")) -> FAIL
A3: Check | B3: Value | C3: Target / Tolerance | D3: Status | E3: Notes
A4: Workbook visible errors | B4: {=SUMPRODUCT(--ISERROR(DCF!A1:L82))+SUMPRODUCT(--ISERROR(WACC!A1:C22))+SUMPRODUCT(--ISERROR('Model Inputs'!A1:F72))+SUMPRODUCT(--ISERROR('Data Queries'!A1:N60))+SUMPRODUCT(--ISERROR('3 Statements'!B1:W45))} -> 0 | C4: 0 | D4: =IF(B4=0,"PASS","FAIL") -> PASS | E4: No visible Excel error values in core ranges.
A5: Scenario selector valid | B5: =DCF!B4 -> 2 | C5: 1, 2, or 3 | D5: =IF(OR(B5=1,B5=2,B5=3),"PASS","FAIL") -> PASS | E5: DCF!B4 must select Bear, Base, or Bull.
A6: Selected case resolves | B6: =DCF!B5 -> Base | C6: Bear / Base / Bull | D6: =IF(OR(B6="Bear",B6="Base",B6="Bull"),"PASS","FAIL") -> PASS | E6: Prevents invalid scenario from cascading through CHOOSE formulas.
A7: Current share price available | B7: ='Model Inputs'!B25 -> 297.84 | C7: > 0 | D7: =IF(B7>0,"PASS","FAIL") -> PASS | E7: Required for market cap and implied upside/downside.
A8: Diluted shares available | B8: ='Model Inputs'!B26 -> 15004697000 | C8: > 0 | D8: =IF(B8>0,"PASS","FAIL") -> PASS | E8: Required for implied value per share.
A9: Current shares available | B9: ='Model Inputs'!B40 -> 14776353000 | C9: > 0 | D9: =IF(B9>0,"PASS","FAIL") -> PASS | E9: Required for market cap and WACC capital structure.
A10: Market cap recomputes | B10: ='Model Inputs'!B27-('Model Inputs'!B25*'Model Inputs'!B40) -> 0 | C10: 0 | D10: =IF(ABS(B10)<1,"PASS","FAIL") -> PASS | E10: Market cap must equal price x current shares.
A11: Base revenue available | B11: ='Model Inputs'!B28 -> 416161000000 | C11: > 0 | D11: =IF(B11>0,"PASS","FAIL") -> PASS | E11: Revenue is the top-line projection driver.
A12: Revenue source status | B12: ='Model Inputs'!D28 -> OK | C12: OK preferred | D12: =IF(B12="OK","PASS",IF(B12="INFERRED","WARN","FAIL")) -> PASS | E12: Inferred revenue can be usable but should be reviewed.
A13: Base EBIT available | B13: ='Model Inputs'!B29 -> 133050000000 | C13: Non-zero | D13: =IF(B13<>0,"PASS","FAIL") -> PASS | E13: EBIT is required for NOPAT and free cash flow.
A14: Base EBIT status | B14: ='Model Inputs'!D29 -> OK | C14: OK | D14: =IF(B14="OK","PASS","FAIL") -> PASS | E14: Missing EBIT must hard fail.
A15: EBIT margin sane | B15: ='Model Inputs'!B30 -> 0.319708 | C15: 0% to 75% | D15: =IF(AND(B15>0,B15<0.75),"PASS","FAIL") -> PASS | E15: Detects missing EBIT, stale revenue, or non-operating company mismatch.
A16: Tax rate sane | B16: ='Model Inputs'!B31 -> 0.15610002 | C16: 0% to 40% | D16: =IF(AND(B16>0,B16<0.4),"PASS","WARN") -> PASS | E16: Actual tax rates outside this range need normalization review.
A17: D&A percent sane | B17: ='Model Inputs'!B32 -> 0.028109313 | C17: 0% to 30% | D17: =IF(AND(B17>0,B17<0.3),"PASS","WARN") -> PASS | E17: Guardrail for stale or missing D&A.
A18: CapEx percent sane | B18: ='Model Inputs'!B33 -> 0.030553079 | C18: 0% to 50% | D18: =IF(AND(B18>0,B18<0.5),"PASS","WARN") -> PASS | E18: Guardrail for stale or missing CapEx.
A19: Cash available | B19: ='Model Inputs'!B34 -> 35934000000 | C19: > 0 | D19: =IF(B19>=0,"PASS","FAIL") -> PASS | E19: Required for net debt bridge.
A20: Debt available | B20: ='Model Inputs'!B35 -> 90678000000 | C20: > 0 | D20: =IF(B20>=0,"PASS","FAIL") -> PASS | E20: Required for net debt and WACC weights.
A21: Net debt numeric | B21: ='Model Inputs'!B36 -> 54744000000 | C21: Number | D21: =IF(ISNUMBER(B21),"PASS","FAIL") -> PASS | E21: Equity value bridge requires numeric net debt/cash.
A22: WACC positive | B22: =WACC!B22 -> 0.097716646 | C22: 0% to 30% | D22: =IF(AND(B22>0,B22<0.3),"PASS","FAIL") -> PASS | E22: Discount rate must be positive and plausible.
A23: WACC > terminal growth | B23: =WACC!B22-'Model Inputs'!B38 -> 0.067716646 | C23: > 0 | D23: =IF(B23>0,"PASS","FAIL") -> PASS | E23: Terminal growth must stay below WACC.
A24: Terminal timing valid | B24: ='Model Inputs'!B22 -> Year-End | C24: Mid-Year / Year-End | D24: =IF(OR(B24="Mid-Year",B24="Year-End"),"PASS","FAIL") -> PASS | E24: Terminal value discount convention must be explicit.
A25: Terminal growth status | B25: ='Model Inputs'!D38 -> OK | C25: OK | D25: =IF(B25="OK","PASS","FAIL") -> PASS | E25: Terminal growth guardrail from Model Inputs.
A26: Cost of debt source/fallback | B26: =IFERROR(INDEX(Cost_of_Debt[FY],1)&" / "&IF(INDEX(Cost_of_Debt[Pre-Tax Cost of Debt],1)>0,TEXT(INDEX(Cost_of_Debt[Pre-Tax Cost of Debt],1),"0.00%"),"n/a"),"missing") -> 2025 / n/a | C26: Current FY or valid manual fallback | D26: =IF(AND(IFERROR(INDEX(Cost_of_Debt[FY],1),0)='Model Inputs'!B39,IFERROR(INDEX(Cost_of_Debt[Pre-Tax Cost of Debt],1),0)>0),"PASS",IF(AND('Model Inputs'!B19>0,'Model Inputs'!B19<0.3),"WARN","FAIL")) -> FAIL | E26: WARN means WACC uses manual debt-cost fallback.
A27: Cost of debt used sane | B27: =WACC!B10 -> 0 | C27: 0% to 30% | D27: =IF(AND(B27>0,B27<0.3),"PASS","FAIL") -> FAIL | E27: WACC cannot rely on zero or implausible debt cost.
A28: Debt/equity weights tie | B28: =WACC!B20+WACC!B21 -> 1 | C28: 1 | D28: =IF(ABS(B28-1)<0.0001,"PASS","FAIL") -> PASS | E28: Capital structure weights must sum to 100%.
A29: Balance sheet balances | B29: =_xlfn.XLOOKUP("Total Assets",EDGAR_BalanceSheet[Line Item],EDGAR_BalanceSheet[Value (USD)],0,0)-_xlfn.XLOOKUP("Total Liabilities & Equity",EDGAR_BalanceSheet[Line Item],EDGAR_BalanceSheet[Value (USD)],0,0) -> 0 | C29: +/- $1,000 | D29: =IF(ABS(B29)<=1000,"PASS","FAIL") -> PASS | E29: Assets should equal liabilities plus equity.
A30: Cash bridge ties | B30: =_xlfn.XLOOKUP("Cash & Equivalents",EDGAR_BalanceSheet[Line Item],EDGAR_BalanceSheet[Value (USD)],0,0)-(_xlfn.XLOOKUP("Cash & Equivalents - Beginning",EDGAR_StatementOfCashFlows[Line Item],EDGAR_StatementOfCashFlows[Value (USD)],0,0)+_xlfn.XLOOKUP("Net Change in Cash",EDGAR_StatementOfCashFlows[Line Item],EDGAR_StatementOfCashFlows[Value (USD)],0,0)) -> 0 | C30: +/- $1,000 | D30: =IF(ABS(B30)<=1000,"PASS","FAIL") -> PASS | E30: Ending cash should equal beginning cash plus net change.
A31: IS/CF net income ties | B31: =_xlfn.XLOOKUP("Net Income",EDGAR_IncomeStatement[Line Item],EDGAR_IncomeStatement[Value],0,0)-_xlfn.XLOOKUP("Net Income",EDGAR_StatementOfCashFlows[Line Item],EDGAR_StatementOfCashFlows[Value (USD)],0,0) -> 0 | C31: +/- $1,000 | D31: =IF(ABS(B31)<=1000,"PASS","FAIL") -> PASS | E31: Net income should match between income statement and cash flow.
A32: Base FY all statements match | B32: =MIN(MAX(EDGAR_IncomeStatement[FY]),MAX(EDGAR_BalanceSheet[FY]),MAX(EDGAR_StatementOfCashFlows[FY])) -> 2025 | C32: Base FY | D32: =IF(B32='Model Inputs'!B39,"PASS","FAIL") -> PASS | E32: All three financial statements should refresh to same fiscal year.
A33: DCF center sensitivity ties | B33: =DCF!B14-DCF!D70 -> 7.2969151 | C33: 0 | D33: =IF(ABS(B33)<0.01,"PASS","FAIL") -> FAIL | E33: WACC/g sensitivity center should equal headline price.
A34: Growth/margin sensitivity ties | B34: =DCF!B14-DCF!D80 -> 7.2969151 | C34: 0 | D34: =IF(ABS(B34)<0.01,"PASS","FAIL") -> FAIL | E34: Growth/margin sensitivity center should equal headline price.
A35: Implied share price positive | B35: =DCF!B14 -> 171.53891 | C35: > 0 | D35: =IF(B35>0,"PASS","FAIL") -> PASS | E35: Final output must be economically usable.
A36: Manual operating overrides active | B36: =COUNTIF('Model Inputs'!C7:C17,TRUE)+COUNTIF('Model Inputs'!C19,TRUE) -> 0 | C36: 0 | D36: =IF(B36=0,"PASS","WARN") -> PASS | E36: Excludes ERP; manual overrides should be deliberate.
A37: Operating company applicability | B37: =IF('Model Inputs'!D29="OK","Operating EBIT available","Missing EBIT / nonstandard operating model") -> Operating EBIT available | C37: Operating EBIT available | D37: =IF(B37="Operating EBIT available","PASS","FAIL") -> PASS | E37: DCF is not durable for nonstandard financials without EBIT mapping.
A38: Source Audit aggregate | B38: =IF(COUNTIF('Source Audit'!E4:E30,"FAIL")>0,"FAIL",IF(COUNTIF('Source Audit'!E4:E30,"WARN")>0,"WARN","PASS")) -> WARN | C38: PASS / WARN | D38: =IF(B38="FAIL","FAIL",IF(B38="WARN","WARN","PASS")) -> WARN | E38: Mirrors source quality dashboard.
A39: StockInformation core fields | B39: =COUNTIF('Data Queries'!E2:E13,"n/a")+COUNTIF('Data Queries'!E2:E13,"") -> 0 | C39: 0 | D39: =IF(B39=0,"PASS","WARN") -> PASS | E39: Warn if quote fields needed for review are missing.
A40: Raw unit integrity | B40: {=SUMPRODUCT(--ISNUMBER(SEARCH("1000"&"000",_xlfn.FORMULATEXT(DCF!A1:L82))))+SUMPRODUCT(--ISNUMBER(SEARCH("1000"&"000",_xlfn.FORMULATEXT(WACC!A1:C22))))+SUMPRODUCT(--ISNUMBER(SEARCH("1000"&"000",_xlfn.FORMULATEXT('Model Inputs'!A1:F72))))} -> 0 | C40: 0 | D40: =IF(B40=0,"PASS","FAIL") -> PASS | E40: No model formulas should scale raw values down to millions.

Sheet Source Audit
A1: Source Audit & Data Quality
A3: Source | B3: Key Field | C3: Observed | D3: Expected / Fallback | E3: Status | F3: Notes
A4: Income Statement | B4: FY | C4: =MAX(EDGAR_IncomeStatement[FY]) -> 2025 | D4: ='Model Inputs'!B39 -> 2025 | E4: =IF(C4=D4,"PASS","FAIL") -> PASS | F4: Latest annual income statement year.
A5: Balance Sheet | B5: FY | C5: =MAX(EDGAR_BalanceSheet[FY]) -> 2025 | D5: ='Model Inputs'!B39 -> 2025 | E5: =IF(C5=D5,"PASS","FAIL") -> PASS | F5: Latest annual balance sheet year.
A6: Cash Flow | B6: FY | C6: =MAX(EDGAR_StatementOfCashFlows[FY]) -> 2025 | D6: ='Model Inputs'!B39 -> 2025 | E6: =IF(C6=D6,"PASS","FAIL") -> PASS | F6: Latest annual cash flow year.
A7: Shares Outstanding | B7: Shares | C7: =IFERROR(INDEX(EDGAR_SharesOutstanding[Shares Outstanding],1),"") -> 14776353000 | D7: > 0 | E7: =IF(C7>0,"PASS","FAIL") -> PASS | F7: Current shares for market cap.
A8: Cost of Debt | B8: FY / Rate | C8: =IFERROR(INDEX(Cost_of_Debt[FY],1)&" / "&IF(INDEX(Cost_of_Debt[Pre-Tax Cost of Debt],1)>0,TEXT(INDEX(Cost_of_Debt[Pre-Tax Cost of Debt],1),"0.00%"),"n/a"),"") -> 2025 / n/a | D8: Base FY with nonblank rate | E8: =IF(AND(IFERROR(INDEX(Cost_of_Debt[FY],1),0)='Model Inputs'!B39,IFERROR(INDEX(Cost_of_Debt[Pre-Tax Cost of Debt],1),0)>0),"PASS","WARN") -> WARN | F8: WARN means WACC uses manual B19 fallback.
A9: Stock Price | B9: Previous Close | C9: ='Data Queries'!E2 -> 297.84 | D9: > 0 | E9: =IF(IFERROR(_xlfn.NUMBERVALUE(C9),0)>0,"PASS","FAIL") -> PASS | F9: Yahoo chart JSON, not HTML scrape.
A10: Beta | B10: Market beta | C10: ='Data Queries'!E11 -> 1.07 | D10: Manual beta B16 | E10: =IF(IFERROR(_xlfn.NUMBERVALUE(C10),0)>0,"PASS","WARN") -> PASS | F10: WARN is acceptable when using manual beta fallback.
A11: 10Y Treasury | B11: Yield | C11: ='Data Queries'!B2 -> 4.623% | D11: > 0 | E11: =IF(IFERROR(_xlfn.NUMBERVALUE(SUBSTITUTE(C11,"%","")),0)>0,"PASS","FAIL") -> PASS | F11: Risk-free rate source.
A12: Tax Rate | B12: Actual tax / PBT | C12: ='Model Inputs'!B31 -> 0.15610002 | D12: 0%-40% | E12: =IF(AND(C12>0,C12<0.4),"PASS","WARN") -> PASS | F12: Normalized tax rate control.
A13: Terminal Value | B13: Discount timing | C13: ='Model Inputs'!B22 -> Year-End | D13: Mid-Year / Year-End | E13: =IF(OR(C13="Mid-Year",C13="Year-End"),"PASS","FAIL") -> PASS | F13: Controls headline and sensitivity terminal discounting.
A16: Refresh Diagnostics
A18: Diagnostic | B18: Observed | C18: Expected | D18: Status | E18: Notes | F18: Formula / Source
A19: Last workbook calculation | B19: =NOW() -> 46161.547 | C19: Timestamp | D19: =IF(B19<>"","PASS","FAIL") -> PASS | E19: Volatile timestamp for review after Refresh All. | F19: =NOW() -> 46161.547
A20: Ticker | B20: =DCF!A3 -> AAPL | C20: Nonblank | D20: =IF(B20<>"","PASS","FAIL") -> PASS | E20: Ticker driving all queries. | F20: =DCF!A3 -> AAPL
A21: Model Checks summary | B21: ='Model Checks'!A2 -> FAIL | C21: PASS / WARN | D21: =IF(B21="FAIL","FAIL",IF(B21="WARN","WARN","PASS")) -> FAIL | E21: Overall hardening status. | F21: ='Model Checks'!A2 -> FAIL
A22: Income statement rows | B22: =ROWS(EDGAR_IncomeStatement[Line Item]) -> 18 | C22: >= 10 | D22: =IF(B22>=10,"PASS","FAIL") -> PASS | E22: Detects empty/failed income-statement query. | F22: =ROWS(EDGAR_IncomeStatement[Line Item]) -> 18
A23: Balance sheet rows | B23: =ROWS(EDGAR_BalanceSheet[Line Item]) -> 27 | C23: >= 20 | D23: =IF(B23>=20,"PASS","FAIL") -> PASS | E23: Detects empty/failed balance-sheet query. | F23: =ROWS(EDGAR_BalanceSheet[Line Item]) -> 27
A24: Cash flow rows | B24: =ROWS(EDGAR_StatementOfCashFlows[Line Item]) -> 24 | C24: >= 15 | D24: =IF(B24>=15,"PASS","FAIL") -> PASS | E24: Detects empty/failed cash-flow query. | F24: =ROWS(EDGAR_StatementOfCashFlows[Line Item]) -> 24
A25: Stock info rows | B25: =ROWS(StockInformation[Metric]) -> 16 | C25: >= 16 | D25: =IF(B25>=16,"PASS","WARN") -> PASS | E25: Detects quote table shape change. | F25: =ROWS(StockInformation[Metric]) -> 16
A26: Unavailable stock fields | B26: =COUNTIF(StockInformation[Value],"n/a")+COUNTIF(StockInformation[Value],"--") -> 0 | C26: 0 preferred | D26: =IF(B26=0,"PASS","WARN") -> PASS | E26: Some fields can be naturally unavailable, but should be visible. | F26: =COUNTIF(StockInformation[Value],"n/a")+COUNTIF(StockInformation[Value],"--") -> 0
A27: Core output hard fails | B27: =COUNTIF('Model Inputs'!D25:D40,"MISSING")+COUNTIF('Model Inputs'!D25:D40,"INVALID*") -> 0 | C27: 0 | D27: =IF(B27=0,"PASS","FAIL") -> PASS | E27: Missing or invalid controlled outputs must fail before relying on valuation.
A28: Controlled output review flags | B28: =COUNTIF('Model Inputs'!D25:D40,"CHECK") -> 0 | C28: 0 preferred | D28: =IF(B28=0,"PASS","WARN") -> PASS | E28: CHECK items should be normalized or manually confirmed.

Sheet Data Queries
A1: Yield | B1: Value | D1: Metric | E1: Value | G1: Related | H1: Last | I1: Previous | J1: Reference
A2: Yield Prev Close | B2: 4.623% | D2: Previous Close | E2: 297.84 | G2: Corporate Tax Rate | H2: 0.21 | I2: 0.21 | J2: Dec 2026
D3: Open | E3: 296.9700012207031 | G3: Personal Income Tax Rate | H3: 0.37 | I3: 0.37 | J3: Dec 2026
D4: Bid | E4: 297.37 x 100 | G4: Sales Tax Rate | H4: 0 | I4: 0 | J4: Dec 2026
D5: Ask | E5: 301.98 x 400 | G5: Social Security Rate | H5: 0.153 | I5: 0.153 | J5: Dec 2026
D6: Day's Range | E6: 296.35 - 300.51 | G6: Social Security Rate For Companies | H6: 0.0765 | I6: 0.0765 | J6: Dec 2026
D7: 52 Week Range | E7: 193.46 - 303.2 | G7: Social Security Rate For Employees | H7: 0.0765 | I7: 0.0765 | J7: Dec 2026
D8: Volume | E8: 18050361 | G8: Withholding Tax Rate | H8: 0.3 | I8: 0.3 | J8: Dec 2025
D9: Avg. Volume | E9: 43155065
D10: Market Cap (intraday) | E10: 4380000000000
D11: Beta (5Y Monthly) | E11: 1.07
D12: PE Ratio (TTM) | E12: 36.058111
D13: EPS (TTM) | E13: 8.26
D14: Earnings Date | E14: Jul 30, 2026
D15: Forward Dividend & Yield | E15: 1.08 (0.36%)
D16: Ex-Dividend Date | E16: May 11, 2026
D17: 1y Target Est | E17: 308.07
A22: Ticker | B22: FY | C22: Company | D22: Interest Expense | E22: Period End | F22: Filed | G22: Debt End | H22: Debt Beginning | I22: Debt Average | J22: Pre-Tax Cost of Debt | K22: Effective Tax Rate | L22: After-Tax Cost of Debt
A23: AAPL | B23: 2025 | C23: Apple Inc. | G23: 90678000000 | H23: 96662000000 | I23: 93670000000 | K23: 0.15610002
A25: Ticker | B25: Company | C25: CIK | D25: Form | E25: FY | F25: FP | G25: As-of | H25: Filed | I25: Shares Outstanding | J25: Accession | K25: Filing URL
A26: AAPL | B26: Apple Inc. | C26: 0000320193 | D26: 10-K | E26: 2025 | F26: FY | G26: 45947 | H26: 45961 | I26: 14776353000 | J26: 0000320193-25-000079 | K26: https://www.sec.gov/Archives/edgar/data/320193/000032019325000079/0000320193-25-000079-index.htm

Sheet Query Setup
A1: Manual Query Setup & Overrides
A3: Area | B3: When to use | C3: Instruction
A4: Refresh | B4: Every model update | C4: Use Data > Refresh All, then confirm Model Checks shows PASS or only expected WARN items.
A5: Stock price | B5: If Source Audit stock price FAILs | C5: Enter price in Model Inputs B7 and set C7 TRUE until the query refreshes cleanly.
A6: Beta | B6: If Source Audit beta WARNs | C6: Review/update Model Inputs B16. This is expected when Yahoo chart JSON does not provide beta.
A7: Cost of debt | B7: If Source Audit Cost of Debt WARNs | C7: Update Model Inputs B19 and leave C19 FALSE unless you intentionally override; WACC rejects stale query years.
A8: Terminal value | B8: To change discount convention | C8: Set Model Inputs B22 to Mid-Year or Year-End.
A9: NWC | B9: To override working capital behavior | C9: Update Model Inputs B20; use Working Capital sheet as a reasonableness check.
A10: Validation | B10: Before relying on valuation | C10: Check Model Checks, Source Audit, and DCF sensitivity center values.
